Workbook

Sheet Assumptions
A1: ARTEFAKT — Year One Budget Assumptions
A2: All figures in Canadian dollars. Blue cells = inputs you can change. All totals update automatically.
A4: LEASE & OPERATING
A5: Item | B5: Value | C5: Notes
A6: Monthly rent (CAD) | B6: 1800 | C6: Negotiate — lower = better
A7: Rent-free months (build-out) | B7: 3 | C7: Months
A8: Lease term (months) | B8: 12 | C8: Year one
A9: Monthly electricity | B9: 200 | C9: Industrial space estimate
A10: Monthly internet | B10: 80 | C10: Commercial fibre
A11: Monthly insurance | B11: 120 | C11: Commercial liability + contents
A12: Monthly accounting | B12: 80 | C12: Bookkeeping + filing
A13: Monthly supplies | B13: 60 | C13: Paper, cleaning, misc
A14: Monthly marketing / print | B14: 50 | C14: Cards, posters, materials
A15: Substack fee rate | B15: 0.1 | C15: 10% of paid subscription revenue
A17: WORKSHOP
A18: Item | B18: Value | C18: Notes
A19: Workshop participants | B19: 12 | C19: Target cohort size
A20: Fee per participant (CAD) | B20: 900 | C20: Conservative — could charge more
A21: Practitioner 1 travel + fee | B21: 3500 | C21: Danny — flights + hotel + honorarium
A22: Practitioner 2 travel + fee | B22: 3500 | C22: Dave — flights + hotel + honorarium
A23: Workshop materials + catering | B23: 600 | C23: Print materials, snacks, supplies
A24: AFA grant (if awarded) | B24: 6500 | C24: Set to 0 if not including grant scenario
A26: SUBSCRIPTIONS
A27: Tier | B27: Rate/mo | C27: Avg subscribers | D27: Active months
A28: The Witness | B28: 25 | C28: 25 | D28: 7
A29: The Practitioner | B29: 75 | C29: 8 | D29: 7
A30: The Patron | B30: 300 | C30: 2 | D30: 7
A32: STUDIO RENTAL
A33: Item | B33: Value | C33: Notes
A34: Day rental rate (CAD) | B34: 250 | C34: Per day
A35: Rental days per month | B35: 2 | C35: Conservative — 2 days/month
A36: Months of rental operation | B36: 8 | C36: Months open for rental

Sheet Build-Out
A1: ARTEFAKT — Build-Out Budget
A2: Blue = input cells. Change any number and totals update automatically. All figures CAD.
A4: Category | B4: Item | C4: Low Est. | D4: High Est. | E4: Your Budget | F4: Notes
A5: FLOORS
B6: Epoxy — main space (1,400 sq ft) | C6: 5600 | D6: 11200 | E6: 7000 | F6: 1,400 sq ft · $4–$8/sq ft
B7: Epoxy — wet lab (200 sq ft) | C7: 800 | D7: 1600 | E7: 1000 | F7: Water-resistant additive
B8: Floor prep + crack repair | C8: 500 | D8: 1200 | E8: 700 | F8: Grinding + patch before coat
A9: FLOORS SUBTOTAL | C9: =SUM(C6:C8) -> 6900 | D9: =SUM(D6:D8) -> 14000 | E9: =SUM(E6:E8) -> 8700
A10: LIGHTING
B11: Track hardware (2 × 40ft runs) | C11: 800 | D11: 1600 | E11: 1000 | F11: WAC or Halo commercial grade
B12: LED track heads × 16 | C12: 960 | D12: 1920 | E12: 1200 | F12: Adjustable 3000K CRI90+
B13: Electrician labour | C13: 800 | D13: 2400 | E13: 1400 | F13: 10–16 hrs at $80–$150/hr Calgary
B14: Panel circuits + wiring (2 × 20A) | C14: 400 | D14: 800 | E14: 500 | F14: Dedicated circuits from panel
B15: Used heads FB Marketplace (offset) | C15: -300 | D15: -600 | E15: -400 | F15: Credit — sourcing savings
A16: LIGHTING SUBTOTAL | C16: =SUM(C11:C15) -> 2660 | D16: =SUM(D11:D15) -> 6120 | E16: =SUM(E11:E15) -> 3700
A17: PLUMBING
B18: Plumber labour | C18: 800 | D18: 2100 | E18: 1200 | F18: 8–14 hrs at $100–$150/hr
B19: Supply line extension + valves | C19: 300 | D19: 600 | E19: 400 | F19: PEX or copper
B20: Drain rough-in + floor drain | C20: 400 | D20: 900 | E20: 550 | F20: Core drill + drain + pipe run
B21: Two utility sinks + taps | C21: 400 | D21: 800 | E21: 550 | F21: Stainless utility sinks
B22: Permits (City of Calgary) | C22: 150 | D22: 300 | E22: 200 | F22: Required for plumbing work
A23: PLUMBING SUBTOTAL | C23: =SUM(C18:C22) -> 2050 | D23: =SUM(D18:D22) -> 4700 | E23: =SUM(E18:E22) -> 2900
A24: WET LAB WALL
B25: Framing + drywall labour | C25: 400 | D25: 800 | E25: 550 | F25: Half day — one 10ft wall
B26: Materials (studs, drywall, mud) | C26: 150 | D26: 300 | E26: 200 | F26: Single wall materials
B27: Paint — wet lab (moisture resistant) | C27: 80 | D27: 150 | E27: 100 | F27: 2 coats
A28: WET LAB WALL SUBTOTAL | C28: =SUM(C25:C27) -> 630 | D28: =SUM(D25:D27) -> 1250 | E28: =SUM(E25:E27) -> 850
A29: PAINT (DIY)
B30: Paint + primer — main space | C30: 300 | D30: 500 | E30: 380 | F30: ~20L flat white — DIY saves labour
A31: PAINT (DIY) SUBTOTAL | C31: =SUM(C30:C30) -> 300 | D31: =SUM(D30:D30) -> 500 | E31: =SUM(E30:E30) -> 380
A32: SHADES
B33: Blackout roller shades × 2 | C33: 200 | D33: 800 | E33: 400 | F33: IKEA TUPPLUR or custom
B34: Installation hardware | C34: 40 | D34: 80 | E34: 50 | F34: Brackets, drill bits
A35: SHADES SUBTOTAL | C35: =SUM(C33:C34) -> 240 | D35: =SUM(D33:D34) -> 880 | E35: =SUM(E33:E34) -> 450
A36: FURNITURE
B37: Large work tables on casters × 2 | C37: 100 | D37: 600 | E37: 300 | F37: 6–8ft · FB Marketplace / Kijiji
B38: Workshop fold-flat tables × 4 | C38: 200 | D38: 600 | E38: 350 | F38: 8ft on casters · used
B39: MCM credenza / sideboard × 1 | C39: 80 | D39: 400 | E39: 200 | F39: FB Marketplace — archive + display
B40: Archive shelving units × 3 | C40: 180 | D40: 500 | E40: 300 | F40: IKEA IVAR or industrial metal
B41: Negative/print storage binders + boxes | C41: 150 | D41: 350 | E41: 220 | F41: Archival sleeves, neg pages
...

Sheet Operating + Revenue
A1: ARTEFAKT — Operating Costs & Revenue (Year One)
A2: All inputs on Assumptions sheet. This sheet shows calculated results. CAD.
A4: SECTION 1 — OPERATING COSTS
A5: Item | B5: Monthly | C5: Months paid | D5: Annual Total | E5: Notes
A6: Rent | B6: =Assumptions!B6 -> 1800 | C6: =Assumptions!B8-Assumptions!B7 -> 9 | D6: =B6*C6 -> 16200 | E6: 3 months free during build-out
A7: Electricity | B7: =Assumptions!B9 -> 200 | C7: =Assumptions!B8 -> 12 | D7: =B7*C7 -> 2400 | E7: Full 12 months
A8: Internet | B8: =Assumptions!B10 -> 80 | C8: =Assumptions!B8 -> 12 | D8: =B8*C8 -> 960 | E8: Full 12 months
A9: Insurance | B9: =Assumptions!B11 -> 120 | C9: =Assumptions!B8 -> 12 | D9: =B9*C9 -> 1440 | E9: Full 12 months
A10: Accounting | B10: =Assumptions!B12 -> 80 | C10: =Assumptions!B8 -> 12 | D10: =B10*C10 -> 960 | E10: Full 12 months
A11: Supplies + consumables | B11: =Assumptions!B13 -> 60 | C11: =Assumptions!B8 -> 12 | D11: =B11*C11 -> 720 | E11: Full 12 months
A12: Marketing + print | B12: =Assumptions!B14 -> 50 | C12: =Assumptions!B8 -> 12 | D12: =B12*C12 -> 600 | E12: Full 12 months
A13: Substack platform fee | B13: =Assumptions!B10*Assumptions!B15 -> 8 | C13: 7 | D13: =B13*C13 -> 56 | E13: ~10% of subscription revenue · 7 months
A14: Website (Format/Squarespace) | B14: 20 | C14: =Assumptions!B8 -> 12 | D14: =B14*C14 -> 240 | E14: Annual plan ~$240
A15: TOTAL OPERATING COSTS | D15: =SUM(D6:D14) -> 23576
A17: SECTION 2 — REVENUE
A18: Revenue Stream | B18: Gross | C18: Costs / Deductions | D18: Net Revenue | E18: Notes
A19: Workshop — gross fees | B19: =Assumptions!B19*Assumptions!B20 -> 10800 | C19: =-(Assumptions!B21+Assumptions!B22+Assumptions!B23) -> -7600 | D19: =B19+C19 -> 3200 | E19: 12 participants × $900 less practitioner costs
A20: AFA Grant (if awarded) | B20: =Assumptions!B24 -> 6500 | C20: — | D20: =B20 -> 6500 | E20: Set to 0 in Assumptions to model without grant
A21: Subscriptions — The Witness | B21: =Assumptions!B28*Assumptions!C28*Assumptions!D28 -> 4375 | C21: =-(B21*Assumptions!B15) -> -437.5 | D21: =B21+C21 -> 3937.5 | E21: Rate × subscribers × months less Substack 10%
A22: Subscriptions — The Practitioner | B22: =Assumptions!B29*Assumptions!C29*Assumptions!D29 -> 4200 | C22: =-(B22*Assumptions!B15) -> -420 | D22: =B22+C22 -> 3780 | E22: Rate × subscribers × months less Substack 10%
A23: Subscriptions — The Patron | B23: =Assumptions!B30*Assumptions!C30*Assumptions!D30 -> 4200 | C23: =-(B23*Assumptions!B15) -> -420 | D23: =B23+C23 -> 3780 | E23: Rate × subscribers × months less Substack 10%
A24: Studio rentals | B24: =Assumptions!B34*Assumptions!B35*Assumptions!B36 -> 4000 | C24: — | D24: =B24 -> 4000 | E24: Day rate × days/month × months open
A25: TOTAL NET REVENUE | D25: =SUM(D19:D24) -> 25197.5
A27: SECTION 3 — YEAR ONE SUMMARY
A28: Starting cash (your savings) | B28: =30000 -> 30000
A29: Total build-out cost | B29: =-'Build-Out'!E62 -> 0
A30: Total operating costs | B30: =-D15 -> -23576
A31: Total net revenue | B31: =D25 -> 25197.5
A32: NET CASH POSITION — END OF YEAR ONE | B32: =B28+B29+B30+B31 -> 31621.5
A34: Tip: On Assumptions sheet, set AFA Grant to 0 to model the scenario without grant funding.

Sheet Monthly Cash Flow
A1: ARTEFAKT — Monthly Cash Flow (Year One)
A2: Indicative month-by-month cash position. All figures CAD.
A4: Month | B4: Activity | C4: Key milestone | D4: In (CAD) | E4: Out (CAD) | F4: Net | G4: Cumulative cash
A5: M 1 | B5: Sign lease · start build-out | C5: Epoxy floor + plumbing | D5: 0 | E5: 8000 | F5: =D5-E5 -> -8000 | G5: =30000+F5 -> 22000
A6: M 2 | B6: Build-out continues | C6: Lighting + furniture sourcing | D6: 0 | E6: 6000 | F6: =D6-E6 -> -6000 | G6: =G5+F6 -> 16000
A7: M 3 | B7: Finish build-out · soft open | C7: Invite founding community | D7: 0 | E7: 3000 | F7: =D7-E7 -> -3000 | G7: =G6+F7 -> 13000
A8: M 4 | B8: Launch dispatch + subscriptions | C8: Issue 001 live · first rent due | D8: 1800 | E8: 3200 | F8: =D8-E8 -> -1400 | G8: =G7+F8 -> 11600
A9: M 5 | B9: Subs grow · first rentals | C9: AFA application submitted | D9: 2800 | E9: 1800 | F9: =D9-E9 -> 1000 | G9: =G8+F9 -> 12600
A10: M 6 | B10: Workshop announced | C10: Applications open to subscribers | D10: 3200 | E10: 2000 | F10: =D10-E10 -> 1200 | G10: =G9+F10 -> 13800
A11: M 7 | B11: Deposits in · AFA result | C11: 6 deposits × $450 | D11: 4200 | E11: 2500 | F11: =D11-E11 -> 1700 | G11: =G10+F11 -> 15500
A12: M 8 | B12: Full workshop payment | C12: 12 participants × $900 | D12: 10800 | E12: 4000 | F12: =D12-E12 -> 6800 | G12: =G11+F12 -> 22300
A13: M 9 | B13: THE WORKSHOP | C13: Danny + Dave in Calgary | D13: 500 | E13: 9600 | F13: =D13-E13 -> -9100 | G13: =G12+F13 -> 13200
A14: M 10 | B14: Post-workshop momentum | C14: New subscribers from workshop | D14: 2800 | E14: 2000 | F14: =D14-E14 -> 800 | G14: =G13+F14 -> 14000
A15: M 11 | B15: AFA grant arrives | C15: Grant disbursement + subs | D15: 10300 | E15: 2000 | F15: =D15-E15 -> 8300 | G15: =G14+F15 -> 22300
A16: M 12 | B16: End of year one | C16: Plan year two | D16: 2800 | E16: 2000 | F16: =D16-E16 -> 800 | G16: =G15+F16 -> 23100
A18: Note: Month 11 AFA grant assumes $6,500 awarded. Set AFA Grant to 0 on Assumptions sheet to model without.
